{
 "cells": [
  {
   "cell_type": "markdown",
   "id": "9f0916d5",
   "metadata": {},
   "source": [
    "# <B> Model Deployment </B>\n",
    "* Container: codna_pytorch_py39"
   ]
  },
  {
   "cell_type": "markdown",
   "id": "95f12c06",
   "metadata": {},
   "source": [
    "## AutoReload"
   ]
  },
  {
   "cell_type": "code",
   "execution_count": 25,
   "id": "87188bfb",
   "metadata": {
    "tags": []
   },
   "outputs": [
    {
     "name": "stdout",
     "output_type": "stream",
     "text": [
      "The autoreload extension is already loaded. To reload it, use:\n",
      "  %reload_ext autoreload\n"
     ]
    }
   ],
   "source": [
    "%load_ext autoreload\n",
    "%autoreload 2"
   ]
  },
  {
   "cell_type": "markdown",
   "id": "122ce182",
   "metadata": {},
   "source": [
    "## 1. parameter store 설정"
   ]
  },
  {
   "cell_type": "code",
   "execution_count": 26,
   "id": "67e463c3",
   "metadata": {
    "tags": []
   },
   "outputs": [],
   "source": [
    "import boto3\n",
    "from utils.ssm import parameter_store"
   ]
  },
  {
   "cell_type": "code",
   "execution_count": 27,
   "id": "615db888",
   "metadata": {
    "tags": []
   },
   "outputs": [],
   "source": [
    "strRegionName=boto3.Session().region_name\n",
    "pm = parameter_store(strRegionName)\n",
    "prefix = pm.get_params(key=\"PREFIX\")"
   ]
  },
  {
   "cell_type": "markdown",
   "id": "40253673",
   "metadata": {},
   "source": [
    "## 2.package import for model deployment"
   ]
  },
  {
   "cell_type": "code",
   "execution_count": 28,
   "id": "f69d0ea4",
   "metadata": {
    "tags": []
   },
   "outputs": [],
   "source": [
    "import os\n",
    "import sagemaker\n",
    "from sagemaker.pytorch.model import PyTorchModel"
   ]
  },
  {
   "cell_type": "code",
   "execution_count": 29,
   "id": "a494fa65",
   "metadata": {
    "tags": []
   },
   "outputs": [],
   "source": [
    "from time import strftime\n",
    "from smexperiments.trial import Trial\n",
    "from smexperiments.experiment import Experiment"
   ]
  },
  {
   "cell_type": "code",
   "execution_count": 30,
   "id": "7caa5ba2",
   "metadata": {
    "tags": []
   },
   "outputs": [],
   "source": [
    "def create_experiment(experiment_name):\n",
    "    try:\n",
    "        sm_experiment = Experiment.load(experiment_name)\n",
    "    except:\n",
    "        sm_experiment = Experiment.create(experiment_name=experiment_name)"
   ]
  },
  {
   "cell_type": "code",
   "execution_count": 31,
   "id": "875fd63c",
   "metadata": {
    "tags": []
   },
   "outputs": [],
   "source": [
    "def create_trial(experiment_name):\n",
    "    create_date = strftime(\"%m%d-%H%M%s\")\n",
    "    sm_trial = Trial.create(trial_name=f'{experiment_name}-{create_date}',\n",
    "                            experiment_name=experiment_name)\n",
    "\n",
    "    job_name = f'{sm_trial.trial_name}'\n",
    "    return job_name"
   ]
  },
  {
   "cell_type": "code",
   "execution_count": 33,
   "id": "e416e7e3",
   "metadata": {
    "tags": []
   },
   "outputs": [
    {
     "ename": "IndexError",
     "evalue": "list index out of range",
     "output_type": "error",
     "traceback": [
      "\u001b[0;31m---------------------------------------------------------------------------\u001b[0m",
      "\u001b[0;31mIndexError\u001b[0m                                Traceback (most recent call last)",
      "\u001b[0;32m/tmp/ipykernel_8908/3688010944.py\u001b[0m in \u001b[0;36m<cell line: 20>\u001b[0;34m()\u001b[0m\n\u001b[1;32m     18\u001b[0m \u001b[0msagemaker_role_arn\u001b[0m \u001b[0;34m=\u001b[0m \u001b[0mpm\u001b[0m\u001b[0;34m.\u001b[0m\u001b[0mget_params\u001b[0m\u001b[0;34m(\u001b[0m\u001b[0mkey\u001b[0m\u001b[0;34m=\u001b[0m\u001b[0mprefix\u001b[0m \u001b[0;34m+\u001b[0m \u001b[0;34m'-SAGEMAKER-ROLE-ARN'\u001b[0m\u001b[0;34m)\u001b[0m\u001b[0;34m\u001b[0m\u001b[0;34m\u001b[0m\u001b[0m\n\u001b[1;32m     19\u001b[0m \u001b[0mbucket_name\u001b[0m \u001b[0;34m=\u001b[0m \u001b[0mpm\u001b[0m\u001b[0;34m.\u001b[0m\u001b[0mget_params\u001b[0m\u001b[0;34m(\u001b[0m\u001b[0mkey\u001b[0m\u001b[0;34m=\u001b[0m\u001b[0mprefix\u001b[0m \u001b[0;34m+\u001b[0m \u001b[0;34m'-BUCKET'\u001b[0m\u001b[0;34m)\u001b[0m\u001b[0;34m\u001b[0m\u001b[0;34m\u001b[0m\u001b[0m\n\u001b[0;32m---> 20\u001b[0;31m \u001b[0mmodel_artifact_s3_uri\u001b[0m \u001b[0;34m=\u001b[0m \u001b[0mpm\u001b[0m\u001b[0;34m.\u001b[0m\u001b[0mget_params\u001b[0m\u001b[0;34m(\u001b[0m\u001b[0mkey\u001b[0m\u001b[0;34m=\u001b[0m\u001b[0mprefix\u001b[0m \u001b[0;34m+\u001b[0m \u001b[0;34m'-MODEL-PATH'\u001b[0m\u001b[0;34m)\u001b[0m\u001b[0;34m\u001b[0m\u001b[0;34m\u001b[0m\u001b[0m\n\u001b[0m\u001b[1;32m     21\u001b[0m \u001b[0minf_image_uri\u001b[0m \u001b[0;34m=\u001b[0m \u001b[0mpm\u001b[0m\u001b[0;34m.\u001b[0m\u001b[0mget_params\u001b[0m\u001b[0;34m(\u001b[0m\u001b[0mkey\u001b[0m\u001b[0;34m=\u001b[0m\u001b[0;34m''\u001b[0m\u001b[0;34m.\u001b[0m\u001b[0mjoin\u001b[0m\u001b[0;34m(\u001b[0m\u001b[0;34m[\u001b[0m\u001b[0mprefix\u001b[0m\u001b[0;34m,\u001b[0m \u001b[0;34m'-INF-IMAGE-URI'\u001b[0m\u001b[0;34m]\u001b[0m\u001b[0;34m)\u001b[0m\u001b[0;34m)\u001b[0m\u001b[0;34m\u001b[0m\u001b[0;34m\u001b[0m\u001b[0m\n\u001b[1;32m     22\u001b[0m \u001b[0;34m\u001b[0m\u001b[0m\n",
      "\u001b[0;32m~/SageMaker/nemo-on-sagemaker/1 building-component/utils/ssm.py\u001b[0m in \u001b[0;36mget_params\u001b[0;34m(self, key, enc)\u001b[0m\n\u001b[1;32m     28\u001b[0m         )\n\u001b[1;32m     29\u001b[0m \u001b[0;34m\u001b[0m\u001b[0m\n\u001b[0;32m---> 30\u001b[0;31m         \u001b[0;32mreturn\u001b[0m \u001b[0mresponse\u001b[0m\u001b[0;34m[\u001b[0m\u001b[0;34m'Parameters'\u001b[0m\u001b[0;34m]\u001b[0m\u001b[0;34m[\u001b[0m\u001b[0;36m0\u001b[0m\u001b[0;34m]\u001b[0m\u001b[0;34m[\u001b[0m\u001b[0;34m'Value'\u001b[0m\u001b[0;34m]\u001b[0m\u001b[0;34m\u001b[0m\u001b[0;34m\u001b[0m\u001b[0m\n\u001b[0m\u001b[1;32m     31\u001b[0m \u001b[0;34m\u001b[0m\u001b[0m\n\u001b[1;32m     32\u001b[0m     \u001b[0;32mdef\u001b[0m \u001b[0mget_all_params\u001b[0m\u001b[0;34m(\u001b[0m\u001b[0mself\u001b[0m\u001b[0;34m,\u001b[0m \u001b[0;34m)\u001b[0m\u001b[0;34m:\u001b[0m\u001b[0;34m\u001b[0m\u001b[0;34m\u001b[0m\u001b[0m\n",
      "\u001b[0;31mIndexError\u001b[0m: list index out of range"
     ]
    }
   ],
   "source": [
    "local_mode = True\n",
    "\n",
    "if local_mode: \n",
    "    inference_instance_type = 'local_gpu'\n",
    "    \n",
    "    import os\n",
    "    from sagemaker.local import LocalSession\n",
    "    \n",
    "    sagemaker_session = LocalSession()\n",
    "    sagemaker_session.config = {'local': {'local_code': True}}\n",
    "    \n",
    "else:\n",
    "    inference_instance_type = \"ml.g4dn.xlarge\"\n",
    "    sagemaker_session = sagemaker.Session()\n",
    "    \n",
    "\n",
    "\n",
    "sagemaker_role_arn = pm.get_params(key=prefix + '-SAGEMAKER-ROLE-ARN')    \n",
    "bucket_name = pm.get_params(key=prefix + '-BUCKET')\n",
    "model_artifact_s3_uri = pm.get_params(key=prefix + '-MODEL-PATH')\n",
    "inf_image_uri = pm.get_params(key=''.join([prefix, '-INF-IMAGE-URI']))\n",
    "\n",
    "code_location= os.path.join(\n",
    "    \"s3://{}\".format(bucket_name),\n",
    "    prefix,\n",
    "    \"inference\",\n",
    "    \"backup_codes\"\n",
    ")\n",
    "\n",
    "monitor_output= os.path.join(\n",
    "    \"s3://{}\".format(bucket_name),\n",
    "    prefix,\n",
    "    \"inference\",\n",
    "    \"monitor_output\"\n",
    ")\n",
    "\n",
    "print (f\"sagemaker_role_arn: {sagemaker_role_arn}\")\n",
    "print (f\"model_artifact_s3_uri: {model_artifact_s3_uri}\")\n",
    "print (f\"inf_image_uri: {inf_image_uri}\")\n",
    "print (f\"code_location: {code_location}\")\n",
    "print (f\"monitor_output: {monitor_output}\")"
   ]
  },
  {
   "cell_type": "markdown",
   "id": "4f5ef566",
   "metadata": {},
   "source": [
    "* Define inference job"
   ]
  },
  {
   "cell_type": "code",
   "execution_count": 22,
   "id": "36a23bac",
   "metadata": {
    "tags": []
   },
   "outputs": [],
   "source": [
    "model = PyTorchModel(\n",
    "    entry_point='predictor.py',\n",
    "    source_dir=os.getcwd() + '/code',\n",
    "    code_location=code_location,\n",
    "    model_data=model_artifact_s3_uri,\n",
    "    role=sagemaker_role_arn,\n",
    "    image_uri=inf_image_uri,\n",
    "    # framework_version=\"1.13.1\",\n",
    "    # py_version=\"py39\",\n",
    "    sagemaker_session=sagemaker_session\n",
    ")"
   ]
  },
  {
   "cell_type": "code",
   "execution_count": 23,
   "id": "6b981409",
   "metadata": {
    "tags": []
   },
   "outputs": [],
   "source": [
    "if local_mode: \n",
    "    data_capture_config = None\n",
    "else:\n",
    "    from sagemaker.model_monitor import DataCaptureConfig\n",
    "\n",
    "    data_capture_config = DataCaptureConfig(\n",
    "        enable_capture=True,\n",
    "        sampling_percentage=100,\n",
    "        destination_s3_uri=monitor_output\n",
    "    )"
   ]
  },
  {
   "cell_type": "code",
   "execution_count": 24,
   "id": "7ae28e0c",
   "metadata": {
    "collapsed": true,
    "jupyter": {
     "outputs_hidden": true
    },
    "tags": []
   },
   "outputs": [
    {
     "name": "stderr",
     "output_type": "stream",
     "text": [
      "INFO:botocore.credentials:Found credentials from IAM Role: BaseNotebookInstanceEc2InstanceRole\n",
      "INFO:botocore.credentials:Found credentials from IAM Role: BaseNotebookInstanceEc2InstanceRole\n",
      "INFO:botocore.credentials:Found credentials from IAM Role: BaseNotebookInstanceEc2InstanceRole\n",
      "INFO:sagemaker:Creating model with name: nemo-test-inference-2023-03-21-03-55-17-720\n",
      "INFO:sagemaker:Creating endpoint-config with name nemo-asr-nemo-experiments-0321-03541679370877\n",
      "INFO:sagemaker:Creating endpoint with name nemo-asr-nemo-experiments-0321-03541679370877\n",
      "INFO:sagemaker.local.image:serving\n",
      "INFO:sagemaker.local.image:creating hosting dir in /tmp/tmpr3uk90n3\n",
      "INFO:botocore.credentials:Found credentials from IAM Role: BaseNotebookInstanceEc2InstanceRole\n",
      "INFO:sagemaker.local.image:No AWS credentials found in session but credentials from EC2 Metadata Service are available.\n",
      "INFO:sagemaker.local.image:docker compose file: \n",
      "networks:\n",
      "  sagemaker-local:\n",
      "    name: sagemaker-local\n",
      "services:\n",
      "  algo-1-et1ba:\n",
      "    command: serve\n",
      "    container_name: nre54rf0z7-algo-1-et1ba\n",
      "    deploy:\n",
      "      resources:\n",
      "        reservations:\n",
      "          devices:\n",
      "          - capabilities:\n",
      "            - gpu\n",
      "    environment:\n",
      "    - '[Masked]'\n",
      "    - '[Masked]'\n",
      "    - '[Masked]'\n",
      "    - '[Masked]'\n",
      "    image: 419974056037.dkr.ecr.ap-northeast-2.amazonaws.com/nemo-test-inference\n",
      "    networks:\n",
      "      sagemaker-local:\n",
      "        aliases:\n",
      "        - algo-1-et1ba\n",
      "    ports:\n",
      "    - 8080:8080\n",
      "    stdin_open: true\n",
      "    tty: true\n",
      "    volumes:\n",
      "    - /tmp/tmpu1mpelgw:/opt/ml/model\n",
      "version: '2.3'\n",
      "\n",
      "INFO:sagemaker.local.image:docker command: docker-compose -f /tmp/tmpr3uk90n3/docker-compose.yaml up --build --abort-on-container-exit\n",
      "INFO:sagemaker.local.entities:Checking if serving container is up, attempt: 5\n",
      "WARNING:urllib3.connectionpool:Retrying (Retry(total=2, connect=None, read=None, redirect=None, status=None)) after connection broken by 'NewConnectionError('<urllib3.connection.HTTPConnection object at 0x7f0ace1eb310>: Failed to establish a new connection: [Errno 111] Connection refused')': /ping\n",
      "WARNING:urllib3.connectionpool:Retrying (Retry(total=1, connect=None, read=None, redirect=None, status=None)) after connection broken by 'NewConnectionError('<urllib3.connection.HTTPConnection object at 0x7f0ace1eb6d0>: Failed to establish a new connection: [Errno 111] Connection refused')': /ping\n",
      "WARNING:urllib3.connectionpool:Retrying (Retry(total=0, connect=None, read=None, redirect=None, status=None)) after connection broken by 'NewConnectionError('<urllib3.connection.HTTPConnection object at 0x7f0ace1eb190>: Failed to establish a new connection: [Errno 111] Connection refused')': /ping\n",
      "INFO:sagemaker.local.entities:Container still not up, got: -1\n"
     ]
    },
    {
     "name": "stdout",
     "output_type": "stream",
     "text": [
      "Attaching to nre54rf0z7-algo-1-et1ba\n",
      "\u001b[36mnre54rf0z7-algo-1-et1ba |\u001b[0m /usr/local/bin/start_with_right_hostname.sh: line 10: serve: command not found\n",
      "\u001b[36mnre54rf0z7-algo-1-et1ba exited with code 127\n",
      "\u001b[0mAborting on container exit...\n"
     ]
    },
    {
     "name": "stderr",
     "output_type": "stream",
     "text": [
      "Exception in thread Thread-5:\n",
      "Traceback (most recent call last):\n",
      "  File \"/home/ec2-user/anaconda3/envs/pytorch_p39/lib/python3.9/site-packages/sagemaker/local/image.py\", line 854, in run\n",
      "    _stream_output(self.process)\n",
      "  File \"/home/ec2-user/anaconda3/envs/pytorch_p39/lib/python3.9/site-packages/sagemaker/local/image.py\", line 916, in _stream_output\n",
      "    raise RuntimeError(\"Process exited with code: %s\" % exit_code)\n",
      "RuntimeError: Process exited with code: 127\n",
      "\n",
      "During handling of the above exception, another exception occurred:\n",
      "\n",
      "Traceback (most recent call last):\n",
      "  File \"/home/ec2-user/anaconda3/envs/pytorch_p39/lib/python3.9/threading.py\", line 980, in _bootstrap_inner\n",
      "    self.run()\n",
      "  File \"/home/ec2-user/anaconda3/envs/pytorch_p39/lib/python3.9/site-packages/sagemaker/local/image.py\", line 859, in run\n",
      "    raise RuntimeError(msg)\n",
      "RuntimeError: Failed to run: ['docker-compose', '-f', '/tmp/tmpr3uk90n3/docker-compose.yaml', 'up', '--build', '--abort-on-container-exit'], Process exited with code: 127\n",
      "INFO:sagemaker.local.entities:Checking if serving container is up, attempt: 10\n",
      "WARNING:urllib3.connectionpool:Retrying (Retry(total=2, connect=None, read=None, redirect=None, status=None)) after connection broken by 'NewConnectionError('<urllib3.connection.HTTPConnection object at 0x7f0ace6ec8e0>: Failed to establish a new connection: [Errno 111] Connection refused')': /ping\n",
      "WARNING:urllib3.connectionpool:Retrying (Retry(total=1, connect=None, read=None, redirect=None, status=None)) after connection broken by 'NewConnectionError('<urllib3.connection.HTTPConnection object at 0x7f0ace1eb220>: Failed to establish a new connection: [Errno 111] Connection refused')': /ping\n",
      "WARNING:urllib3.connectionpool:Retrying (Retry(total=0, connect=None, read=None, redirect=None, status=None)) after connection broken by 'NewConnectionError('<urllib3.connection.HTTPConnection object at 0x7f0ace22c280>: Failed to establish a new connection: [Errno 111] Connection refused')': /ping\n",
      "INFO:sagemaker.local.entities:Container still not up, got: -1\n",
      "INFO:sagemaker.local.entities:Checking if serving container is up, attempt: 15\n",
      "WARNING:urllib3.connectionpool:Retrying (Retry(total=2, connect=None, read=None, redirect=None, status=None)) after connection broken by 'NewConnectionError('<urllib3.connection.HTTPConnection object at 0x7f0ace22c640>: Failed to establish a new connection: [Errno 111] Connection refused')': /ping\n",
      "WARNING:urllib3.connectionpool:Retrying (Retry(total=1, connect=None, read=None, redirect=None, status=None)) after connection broken by 'NewConnectionError('<urllib3.connection.HTTPConnection object at 0x7f0ace22ca60>: Failed to establish a new connection: [Errno 111] Connection refused')': /ping\n",
      "WARNING:urllib3.connectionpool:Retrying (Retry(total=0, connect=None, read=None, redirect=None, status=None)) after connection broken by 'NewConnectionError('<urllib3.connection.HTTPConnection object at 0x7f0ace22c340>: Failed to establish a new connection: [Errno 111] Connection refused')': /ping\n",
      "INFO:sagemaker.local.entities:Container still not up, got: -1\n",
      "INFO:sagemaker.local.entities:Checking if serving container is up, attempt: 20\n",
      "WARNING:urllib3.connectionpool:Retrying (Retry(total=2, connect=None, read=None, redirect=None, status=None)) after connection broken by 'NewConnectionError('<urllib3.connection.HTTPConnection object at 0x7f0ace233850>: Failed to establish a new connection: [Errno 111] Connection refused')': /ping\n",
      "WARNING:urllib3.connectionpool:Retrying (Retry(total=1, connect=None, read=None, redirect=None, status=None)) after connection broken by 'NewConnectionError('<urllib3.connection.HTTPConnection object at 0x7f0ace220c70>: Failed to establish a new connection: [Errno 111] Connection refused')': /ping\n",
      "WARNING:urllib3.connectionpool:Retrying (Retry(total=0, connect=None, read=None, redirect=None, status=None)) after connection broken by 'NewConnectionError('<urllib3.connection.HTTPConnection object at 0x7f0ace220760>: Failed to establish a new connection: [Errno 111] Connection refused')': /ping\n",
      "INFO:sagemaker.local.entities:Container still not up, got: -1\n",
      "INFO:sagemaker.local.entities:Checking if serving container is up, attempt: 25\n",
      "WARNING:urllib3.connectionpool:Retrying (Retry(total=2, connect=None, read=None, redirect=None, status=None)) after connection broken by 'NewConnectionError('<urllib3.connection.HTTPConnection object at 0x7f0ace220370>: Failed to establish a new connection: [Errno 111] Connection refused')': /ping\n",
      "WARNING:urllib3.connectionpool:Retrying (Retry(total=1, connect=None, read=None, redirect=None, status=None)) after connection broken by 'NewConnectionError('<urllib3.connection.HTTPConnection object at 0x7f0ace2201c0>: Failed to establish a new connection: [Errno 111] Connection refused')': /ping\n",
      "WARNING:urllib3.connectionpool:Retrying (Retry(total=0, connect=None, read=None, redirect=None, status=None)) after connection broken by 'NewConnectionError('<urllib3.connection.HTTPConnection object at 0x7f0ace22c820>: Failed to establish a new connection: [Errno 111] Connection refused')': /ping\n",
      "INFO:sagemaker.local.entities:Container still not up, got: -1\n",
      "INFO:sagemaker.local.entities:Checking if serving container is up, attempt: 30\n",
      "WARNING:urllib3.connectionpool:Retrying (Retry(total=2, connect=None, read=None, redirect=None, status=None)) after connection broken by 'NewConnectionError('<urllib3.connection.HTTPConnection object at 0x7f0ace22c910>: Failed to establish a new connection: [Errno 111] Connection refused')': /ping\n",
      "WARNING:urllib3.connectionpool:Retrying (Retry(total=1, connect=None, read=None, redirect=None, status=None)) after connection broken by 'NewConnectionError('<urllib3.connection.HTTPConnection object at 0x7f0ace22c130>: Failed to establish a new connection: [Errno 111] Connection refused')': /ping\n",
      "WARNING:urllib3.connectionpool:Retrying (Retry(total=0, connect=None, read=None, redirect=None, status=None)) after connection broken by 'NewConnectionError('<urllib3.connection.HTTPConnection object at 0x7f0ace22cfd0>: Failed to establish a new connection: [Errno 111] Connection refused')': /ping\n",
      "INFO:sagemaker.local.entities:Container still not up, got: -1\n",
      "INFO:sagemaker.local.entities:Checking if serving container is up, attempt: 35\n",
      "WARNING:urllib3.connectionpool:Retrying (Retry(total=2, connect=None, read=None, redirect=None, status=None)) after connection broken by 'NewConnectionError('<urllib3.connection.HTTPConnection object at 0x7f0ace22c730>: Failed to establish a new connection: [Errno 111] Connection refused')': /ping\n",
      "WARNING:urllib3.connectionpool:Retrying (Retry(total=1, connect=None, read=None, redirect=None, status=None)) after connection broken by 'NewConnectionError('<urllib3.connection.HTTPConnection object at 0x7f0ace1eb940>: Failed to establish a new connection: [Errno 111] Connection refused')': /ping\n",
      "WARNING:urllib3.connectionpool:Retrying (Retry(total=0, connect=None, read=None, redirect=None, status=None)) after connection broken by 'NewConnectionError('<urllib3.connection.HTTPConnection object at 0x7f0ace1ebee0>: Failed to establish a new connection: [Errno 111] Connection refused')': /ping\n",
      "INFO:sagemaker.local.entities:Container still not up, got: -1\n",
      "INFO:sagemaker.local.entities:Checking if serving container is up, attempt: 40\n",
      "WARNING:urllib3.connectionpool:Retrying (Retry(total=2, connect=None, read=None, redirect=None, status=None)) after connection broken by 'NewConnectionError('<urllib3.connection.HTTPConnection object at 0x7f0ace1eb6d0>: Failed to establish a new connection: [Errno 111] Connection refused')': /ping\n",
      "WARNING:urllib3.connectionpool:Retrying (Retry(total=1, connect=None, read=None, redirect=None, status=None)) after connection broken by 'NewConnectionError('<urllib3.connection.HTTPConnection object at 0x7f0ace2514f0>: Failed to establish a new connection: [Errno 111] Connection refused')': /ping\n",
      "WARNING:urllib3.connectionpool:Retrying (Retry(total=0, connect=None, read=None, redirect=None, status=None)) after connection broken by 'NewConnectionError('<urllib3.connection.HTTPConnection object at 0x7f0ace251070>: Failed to establish a new connection: [Errno 111] Connection refused')': /ping\n",
      "INFO:sagemaker.local.entities:Container still not up, got: -1\n",
      "INFO:sagemaker.local.entities:Checking if serving container is up, attempt: 45\n",
      "WARNING:urllib3.connectionpool:Retrying (Retry(total=2, connect=None, read=None, redirect=None, status=None)) after connection broken by 'NewConnectionError('<urllib3.connection.HTTPConnection object at 0x7f0ace249610>: Failed to establish a new connection: [Errno 111] Connection refused')': /ping\n",
      "WARNING:urllib3.connectionpool:Retrying (Retry(total=1, connect=None, read=None, redirect=None, status=None)) after connection broken by 'NewConnectionError('<urllib3.connection.HTTPConnection object at 0x7f0ace2495e0>: Failed to establish a new connection: [Errno 111] Connection refused')': /ping\n",
      "WARNING:urllib3.connectionpool:Retrying (Retry(total=0, connect=None, read=None, redirect=None, status=None)) after connection broken by 'NewConnectionError('<urllib3.connection.HTTPConnection object at 0x7f0ace421640>: Failed to establish a new connection: [Errno 111] Connection refused')': /ping\n",
      "INFO:sagemaker.local.entities:Container still not up, got: -1\n",
      "INFO:sagemaker.local.entities:Checking if serving container is up, attempt: 50\n",
      "WARNING:urllib3.connectionpool:Retrying (Retry(total=2, connect=None, read=None, redirect=None, status=None)) after connection broken by 'NewConnectionError('<urllib3.connection.HTTPConnection object at 0x7f0ace215bb0>: Failed to establish a new connection: [Errno 111] Connection refused')': /ping\n",
      "WARNING:urllib3.connectionpool:Retrying (Retry(total=1, connect=None, read=None, redirect=None, status=None)) after connection broken by 'NewConnectionError('<urllib3.connection.HTTPConnection object at 0x7f0ace215a30>: Failed to establish a new connection: [Errno 111] Connection refused')': /ping\n",
      "WARNING:urllib3.connectionpool:Retrying (Retry(total=0, connect=None, read=None, redirect=None, status=None)) after connection broken by 'NewConnectionError('<urllib3.connection.HTTPConnection object at 0x7f0ace421340>: Failed to establish a new connection: [Errno 111] Connection refused')': /ping\n",
      "INFO:sagemaker.local.entities:Container still not up, got: -1\n",
      "INFO:sagemaker.local.entities:Checking if serving container is up, attempt: 55\n",
      "WARNING:urllib3.connectionpool:Retrying (Retry(total=2, connect=None, read=None, redirect=None, status=None)) after connection broken by 'NewConnectionError('<urllib3.connection.HTTPConnection object at 0x7f0ace249280>: Failed to establish a new connection: [Errno 111] Connection refused')': /ping\n",
      "WARNING:urllib3.connectionpool:Retrying (Retry(total=1, connect=None, read=None, redirect=None, status=None)) after connection broken by 'NewConnectionError('<urllib3.connection.HTTPConnection object at 0x7f0ace251a90>: Failed to establish a new connection: [Errno 111] Connection refused')': /ping\n",
      "WARNING:urllib3.connectionpool:Retrying (Retry(total=0, connect=None, read=None, redirect=None, status=None)) after connection broken by 'NewConnectionError('<urllib3.connection.HTTPConnection object at 0x7f0ace251730>: Failed to establish a new connection: [Errno 111] Connection refused')': /ping\n",
      "INFO:sagemaker.local.entities:Container still not up, got: -1\n",
      "INFO:sagemaker.local.entities:Checking if serving container is up, attempt: 60\n",
      "WARNING:urllib3.connectionpool:Retrying (Retry(total=2, connect=None, read=None, redirect=None, status=None)) after connection broken by 'NewConnectionError('<urllib3.connection.HTTPConnection object at 0x7f0ace1eb100>: Failed to establish a new connection: [Errno 111] Connection refused')': /ping\n",
      "WARNING:urllib3.connectionpool:Retrying (Retry(total=1, connect=None, read=None, redirect=None, status=None)) after connection broken by 'NewConnectionError('<urllib3.connection.HTTPConnection object at 0x7f0ace1eb7f0>: Failed to establish a new connection: [Errno 111] Connection refused')': /ping\n",
      "WARNING:urllib3.connectionpool:Retrying (Retry(total=0, connect=None, read=None, redirect=None, status=None)) after connection broken by 'NewConnectionError('<urllib3.connection.HTTPConnection object at 0x7f0ace1eb220>: Failed to establish a new connection: [Errno 111] Connection refused')': /ping\n",
      "INFO:sagemaker.local.entities:Container still not up, got: -1\n",
      "INFO:sagemaker.local.entities:Checking if serving container is up, attempt: 65\n",
      "WARNING:urllib3.connectionpool:Retrying (Retry(total=2, connect=None, read=None, redirect=None, status=None)) after connection broken by 'NewConnectionError('<urllib3.connection.HTTPConnection object at 0x7f0ace22c070>: Failed to establish a new connection: [Errno 111] Connection refused')': /ping\n",
      "WARNING:urllib3.connectionpool:Retrying (Retry(total=1, connect=None, read=None, redirect=None, status=None)) after connection broken by 'NewConnectionError('<urllib3.connection.HTTPConnection object at 0x7f0ace22c310>: Failed to establish a new connection: [Errno 111] Connection refused')': /ping\n",
      "WARNING:urllib3.connectionpool:Retrying (Retry(total=0, connect=None, read=None, redirect=None, status=None)) after connection broken by 'NewConnectionError('<urllib3.connection.HTTPConnection object at 0x7f0ace22c2e0>: Failed to establish a new connection: [Errno 111] Connection refused')': /ping\n",
      "INFO:sagemaker.local.entities:Container still not up, got: -1\n",
      "INFO:sagemaker.local.entities:Checking if serving container is up, attempt: 70\n",
      "WARNING:urllib3.connectionpool:Retrying (Retry(total=2, connect=None, read=None, redirect=None, status=None)) after connection broken by 'NewConnectionError('<urllib3.connection.HTTPConnection object at 0x7f0ace22c340>: Failed to establish a new connection: [Errno 111] Connection refused')': /ping\n",
      "WARNING:urllib3.connectionpool:Retrying (Retry(total=1, connect=None, read=None, redirect=None, status=None)) after connection broken by 'NewConnectionError('<urllib3.connection.HTTPConnection object at 0x7f0ace22c850>: Failed to establish a new connection: [Errno 111] Connection refused')': /ping\n",
      "WARNING:urllib3.connectionpool:Retrying (Retry(total=0, connect=None, read=None, redirect=None, status=None)) after connection broken by 'NewConnectionError('<urllib3.connection.HTTPConnection object at 0x7f0ace22c820>: Failed to establish a new connection: [Errno 111] Connection refused')': /ping\n",
      "INFO:sagemaker.local.entities:Container still not up, got: -1\n",
      "INFO:sagemaker.local.entities:Checking if serving container is up, attempt: 75\n",
      "WARNING:urllib3.connectionpool:Retrying (Retry(total=2, connect=None, read=None, redirect=None, status=None)) after connection broken by 'NewConnectionError('<urllib3.connection.HTTPConnection object at 0x7f0ace215d00>: Failed to establish a new connection: [Errno 111] Connection refused')': /ping\n",
      "WARNING:urllib3.connectionpool:Retrying (Retry(total=1, connect=None, read=None, redirect=None, status=None)) after connection broken by 'NewConnectionError('<urllib3.connection.HTTPConnection object at 0x7f0ace2157f0>: Failed to establish a new connection: [Errno 111] Connection refused')': /ping\n",
      "WARNING:urllib3.connectionpool:Retrying (Retry(total=0, connect=None, read=None, redirect=None, status=None)) after connection broken by 'NewConnectionError('<urllib3.connection.HTTPConnection object at 0x7f0ace22ce50>: Failed to establish a new connection: [Errno 111] Connection refused')': /ping\n",
      "INFO:sagemaker.local.entities:Container still not up, got: -1\n",
      "INFO:sagemaker.local.entities:Checking if serving container is up, attempt: 80\n",
      "WARNING:urllib3.connectionpool:Retrying (Retry(total=2, connect=None, read=None, redirect=None, status=None)) after connection broken by 'NewConnectionError('<urllib3.connection.HTTPConnection object at 0x7f0ace22c280>: Failed to establish a new connection: [Errno 111] Connection refused')': /ping\n",
      "WARNING:urllib3.connectionpool:Retrying (Retry(total=1, connect=None, read=None, redirect=None, status=None)) after connection broken by 'NewConnectionError('<urllib3.connection.HTTPConnection object at 0x7f0ace22cbe0>: Failed to establish a new connection: [Errno 111] Connection refused')': /ping\n",
      "WARNING:urllib3.connectionpool:Retrying (Retry(total=0, connect=None, read=None, redirect=None, status=None)) after connection broken by 'NewConnectionError('<urllib3.connection.HTTPConnection object at 0x7f0ace22c730>: Failed to establish a new connection: [Errno 111] Connection refused')': /ping\n",
      "INFO:sagemaker.local.entities:Container still not up, got: -1\n",
      "INFO:sagemaker.local.entities:Checking if serving container is up, attempt: 85\n",
      "WARNING:urllib3.connectionpool:Retrying (Retry(total=2, connect=None, read=None, redirect=None, status=None)) after connection broken by 'NewConnectionError('<urllib3.connection.HTTPConnection object at 0x7f0ace22cc10>: Failed to establish a new connection: [Errno 111] Connection refused')': /ping\n",
      "WARNING:urllib3.connectionpool:Retrying (Retry(total=1, connect=None, read=None, redirect=None, status=None)) after connection broken by 'NewConnectionError('<urllib3.connection.HTTPConnection object at 0x7f0ace1ebee0>: Failed to establish a new connection: [Errno 111] Connection refused')': /ping\n",
      "WARNING:urllib3.connectionpool:Retrying (Retry(total=0, connect=None, read=None, redirect=None, status=None)) after connection broken by 'NewConnectionError('<urllib3.connection.HTTPConnection object at 0x7f0ace1eb7f0>: Failed to establish a new connection: [Errno 111] Connection refused')': /ping\n",
      "INFO:sagemaker.local.entities:Container still not up, got: -1\n",
      "INFO:sagemaker.local.entities:Checking if serving container is up, attempt: 90\n",
      "WARNING:urllib3.connectionpool:Retrying (Retry(total=2, connect=None, read=None, redirect=None, status=None)) after connection broken by 'NewConnectionError('<urllib3.connection.HTTPConnection object at 0x7f0ace1eb220>: Failed to establish a new connection: [Errno 111] Connection refused')': /ping\n",
      "WARNING:urllib3.connectionpool:Retrying (Retry(total=1, connect=None, read=None, redirect=None, status=None)) after connection broken by 'NewConnectionError('<urllib3.connection.HTTPConnection object at 0x7f0ace251bb0>: Failed to establish a new connection: [Errno 111] Connection refused')': /ping\n",
      "WARNING:urllib3.connectionpool:Retrying (Retry(total=0, connect=None, read=None, redirect=None, status=None)) after connection broken by 'NewConnectionError('<urllib3.connection.HTTPConnection object at 0x7f0ace251820>: Failed to establish a new connection: [Errno 111] Connection refused')': /ping\n",
      "INFO:sagemaker.local.entities:Container still not up, got: -1\n",
      "INFO:sagemaker.local.entities:Checking if serving container is up, attempt: 95\n",
      "WARNING:urllib3.connectionpool:Retrying (Retry(total=2, connect=None, read=None, redirect=None, status=None)) after connection broken by 'NewConnectionError('<urllib3.connection.HTTPConnection object at 0x7f0ace895070>: Failed to establish a new connection: [Errno 111] Connection refused')': /ping\n",
      "WARNING:urllib3.connectionpool:Retrying (Retry(total=1, connect=None, read=None, redirect=None, status=None)) after connection broken by 'NewConnectionError('<urllib3.connection.HTTPConnection object at 0x7f0ace249490>: Failed to establish a new connection: [Errno 111] Connection refused')': /ping\n",
      "WARNING:urllib3.connectionpool:Retrying (Retry(total=0, connect=None, read=None, redirect=None, status=None)) after connection broken by 'NewConnectionError('<urllib3.connection.HTTPConnection object at 0x7f0ace215850>: Failed to establish a new connection: [Errno 111] Connection refused')': /ping\n",
      "INFO:sagemaker.local.entities:Container still not up, got: -1\n",
      "INFO:sagemaker.local.entities:Checking if serving container is up, attempt: 100\n",
      "WARNING:urllib3.connectionpool:Retrying (Retry(total=2, connect=None, read=None, redirect=None, status=None)) after connection broken by 'NewConnectionError('<urllib3.connection.HTTPConnection object at 0x7f0ace215e20>: Failed to establish a new connection: [Errno 111] Connection refused')': /ping\n",
      "WARNING:urllib3.connectionpool:Retrying (Retry(total=1, connect=None, read=None, redirect=None, status=None)) after connection broken by 'NewConnectionError('<urllib3.connection.HTTPConnection object at 0x7f0ace263580>: Failed to establish a new connection: [Errno 111] Connection refused')': /ping\n",
      "WARNING:urllib3.connectionpool:Retrying (Retry(total=0, connect=None, read=None, redirect=None, status=None)) after connection broken by 'NewConnectionError('<urllib3.connection.HTTPConnection object at 0x7f0ace263340>: Failed to establish a new connection: [Errno 111] Connection refused')': /ping\n",
      "INFO:sagemaker.local.entities:Container still not up, got: -1\n",
      "INFO:sagemaker.local.entities:Checking if serving container is up, attempt: 105\n",
      "WARNING:urllib3.connectionpool:Retrying (Retry(total=2, connect=None, read=None, redirect=None, status=None)) after connection broken by 'NewConnectionError('<urllib3.connection.HTTPConnection object at 0x7f0ace215d90>: Failed to establish a new connection: [Errno 111] Connection refused')': /ping\n",
      "WARNING:urllib3.connectionpool:Retrying (Retry(total=1, connect=None, read=None, redirect=None, status=None)) after connection broken by 'NewConnectionError('<urllib3.connection.HTTPConnection object at 0x7f0ace2497f0>: Failed to establish a new connection: [Errno 111] Connection refused')': /ping\n",
      "WARNING:urllib3.connectionpool:Retrying (Retry(total=0, connect=None, read=None, redirect=None, status=None)) after connection broken by 'NewConnectionError('<urllib3.connection.HTTPConnection object at 0x7f0ace249eb0>: Failed to establish a new connection: [Errno 111] Connection refused')': /ping\n",
      "INFO:sagemaker.local.entities:Container still not up, got: -1\n",
      "INFO:sagemaker.local.entities:Checking if serving container is up, attempt: 110\n",
      "WARNING:urllib3.connectionpool:Retrying (Retry(total=2, connect=None, read=None, redirect=None, status=None)) after connection broken by 'NewConnectionError('<urllib3.connection.HTTPConnection object at 0x7f0ace251ee0>: Failed to establish a new connection: [Errno 111] Connection refused')': /ping\n",
      "WARNING:urllib3.connectionpool:Retrying (Retry(total=1, connect=None, read=None, redirect=None, status=None)) after connection broken by 'NewConnectionError('<urllib3.connection.HTTPConnection object at 0x7f0ace251160>: Failed to establish a new connection: [Errno 111] Connection refused')': /ping\n",
      "WARNING:urllib3.connectionpool:Retrying (Retry(total=0, connect=None, read=None, redirect=None, status=None)) after connection broken by 'NewConnectionError('<urllib3.connection.HTTPConnection object at 0x7f0ace1eb3a0>: Failed to establish a new connection: [Errno 111] Connection refused')': /ping\n",
      "INFO:sagemaker.local.entities:Container still not up, got: -1\n",
      "INFO:sagemaker.local.entities:Checking if serving container is up, attempt: 115\n",
      "WARNING:urllib3.connectionpool:Retrying (Retry(total=2, connect=None, read=None, redirect=None, status=None)) after connection broken by 'NewConnectionError('<urllib3.connection.HTTPConnection object at 0x7f0ace1eb400>: Failed to establish a new connection: [Errno 111] Connection refused')': /ping\n",
      "WARNING:urllib3.connectionpool:Retrying (Retry(total=1, connect=None, read=None, redirect=None, status=None)) after connection broken by 'NewConnectionError('<urllib3.connection.HTTPConnection object at 0x7f0ace1ebc40>: Failed to establish a new connection: [Errno 111] Connection refused')': /ping\n",
      "WARNING:urllib3.connectionpool:Retrying (Retry(total=0, connect=None, read=None, redirect=None, status=None)) after connection broken by 'NewConnectionError('<urllib3.connection.HTTPConnection object at 0x7f0ace22c6a0>: Failed to establish a new connection: [Errno 111] Connection refused')': /ping\n",
      "INFO:sagemaker.local.entities:Container still not up, got: -1\n"
     ]
    },
    {
     "ename": "RuntimeError",
     "evalue": "Giving up, endpoint didn't launch correctly",
     "output_type": "error",
     "traceback": [
      "\u001b[0;31m---------------------------------------------------------------------------\u001b[0m",
      "\u001b[0;31mRuntimeError\u001b[0m                              Traceback (most recent call last)",
      "\u001b[0;32m/tmp/ipykernel_8908/2668115592.py\u001b[0m in \u001b[0;36m<cell line: 6>\u001b[0;34m()\u001b[0m\n\u001b[1;32m      4\u001b[0m \u001b[0;34m\u001b[0m\u001b[0m\n\u001b[1;32m      5\u001b[0m \u001b[0;34m\u001b[0m\u001b[0m\n\u001b[0;32m----> 6\u001b[0;31m predictor = model.deploy(\n\u001b[0m\u001b[1;32m      7\u001b[0m     \u001b[0minitial_instance_count\u001b[0m\u001b[0;34m=\u001b[0m\u001b[0;36m1\u001b[0m\u001b[0;34m,\u001b[0m\u001b[0;34m\u001b[0m\u001b[0;34m\u001b[0m\u001b[0m\n\u001b[1;32m      8\u001b[0m     \u001b[0minstance_type\u001b[0m\u001b[0;34m=\u001b[0m\u001b[0minference_instance_type\u001b[0m\u001b[0;34m,\u001b[0m\u001b[0;34m\u001b[0m\u001b[0;34m\u001b[0m\u001b[0m\n",
      "\u001b[0;32m~/anaconda3/envs/pytorch_p39/lib/python3.9/site-packages/sagemaker/model.py\u001b[0m in \u001b[0;36mdeploy\u001b[0;34m(self, initial_instance_count, instance_type, serializer, deserializer, accelerator_type, endpoint_name, tags, kms_key, wait, data_capture_config, async_inference_config, serverless_inference_config, volume_size, model_data_download_timeout, container_startup_health_check_timeout, inference_recommendation_id, **kwargs)\u001b[0m\n\u001b[1;32m   1219\u001b[0m             \u001b[0masync_inference_config_dict\u001b[0m \u001b[0;34m=\u001b[0m \u001b[0masync_inference_config\u001b[0m\u001b[0;34m.\u001b[0m\u001b[0m_to_request_dict\u001b[0m\u001b[0;34m(\u001b[0m\u001b[0;34m)\u001b[0m\u001b[0;34m\u001b[0m\u001b[0;34m\u001b[0m\u001b[0m\n\u001b[1;32m   1220\u001b[0m \u001b[0;34m\u001b[0m\u001b[0m\n\u001b[0;32m-> 1221\u001b[0;31m         self.sagemaker_session.endpoint_from_production_variants(\n\u001b[0m\u001b[1;32m   1222\u001b[0m             \u001b[0mname\u001b[0m\u001b[0;34m=\u001b[0m\u001b[0mself\u001b[0m\u001b[0;34m.\u001b[0m\u001b[0mendpoint_name\u001b[0m\u001b[0;34m,\u001b[0m\u001b[0;34m\u001b[0m\u001b[0;34m\u001b[0m\u001b[0m\n\u001b[1;32m   1223\u001b[0m             \u001b[0mproduction_variants\u001b[0m\u001b[0;34m=\u001b[0m\u001b[0;34m[\u001b[0m\u001b[0mproduction_variant\u001b[0m\u001b[0;34m]\u001b[0m\u001b[0;34m,\u001b[0m\u001b[0;34m\u001b[0m\u001b[0;34m\u001b[0m\u001b[0m\n",
      "\u001b[0;32m~/anaconda3/envs/pytorch_p39/lib/python3.9/site-packages/sagemaker/session.py\u001b[0m in \u001b[0;36mendpoint_from_production_variants\u001b[0;34m(self, name, production_variants, tags, kms_key, wait, data_capture_config_dict, async_inference_config_dict)\u001b[0m\n\u001b[1;32m   3995\u001b[0m         \u001b[0mself\u001b[0m\u001b[0;34m.\u001b[0m\u001b[0msagemaker_client\u001b[0m\u001b[0;34m.\u001b[0m\u001b[0mcreate_endpoint_config\u001b[0m\u001b[0;34m(\u001b[0m\u001b[0;34m**\u001b[0m\u001b[0mconfig_options\u001b[0m\u001b[0;34m)\u001b[0m\u001b[0;34m\u001b[0m\u001b[0;34m\u001b[0m\u001b[0m\n\u001b[1;32m   3996\u001b[0m \u001b[0;34m\u001b[0m\u001b[0m\n\u001b[0;32m-> 3997\u001b[0;31m         \u001b[0;32mreturn\u001b[0m \u001b[0mself\u001b[0m\u001b[0;34m.\u001b[0m\u001b[0mcreate_endpoint\u001b[0m\u001b[0;34m(\u001b[0m\u001b[0mendpoint_name\u001b[0m\u001b[0;34m=\u001b[0m\u001b[0mname\u001b[0m\u001b[0;34m,\u001b[0m \u001b[0mconfig_name\u001b[0m\u001b[0;34m=\u001b[0m\u001b[0mname\u001b[0m\u001b[0;34m,\u001b[0m \u001b[0mtags\u001b[0m\u001b[0;34m=\u001b[0m\u001b[0mtags\u001b[0m\u001b[0;34m,\u001b[0m \u001b[0mwait\u001b[0m\u001b[0;34m=\u001b[0m\u001b[0mwait\u001b[0m\u001b[0;34m)\u001b[0m\u001b[0;34m\u001b[0m\u001b[0;34m\u001b[0m\u001b[0m\n\u001b[0m\u001b[1;32m   3998\u001b[0m \u001b[0;34m\u001b[0m\u001b[0m\n\u001b[1;32m   3999\u001b[0m     \u001b[0;32mdef\u001b[0m \u001b[0mexpand_role\u001b[0m\u001b[0;34m(\u001b[0m\u001b[0mself\u001b[0m\u001b[0;34m,\u001b[0m \u001b[0mrole\u001b[0m\u001b[0;34m)\u001b[0m\u001b[0;34m:\u001b[0m\u001b[0;34m\u001b[0m\u001b[0;34m\u001b[0m\u001b[0m\n",
      "\u001b[0;32m~/anaconda3/envs/pytorch_p39/lib/python3.9/site-packages/sagemaker/session.py\u001b[0m in \u001b[0;36mcreate_endpoint\u001b[0;34m(self, endpoint_name, config_name, tags, wait)\u001b[0m\n\u001b[1;32m   3467\u001b[0m         \u001b[0mtags\u001b[0m \u001b[0;34m=\u001b[0m \u001b[0m_append_project_tags\u001b[0m\u001b[0;34m(\u001b[0m\u001b[0mtags\u001b[0m\u001b[0;34m)\u001b[0m\u001b[0;34m\u001b[0m\u001b[0;34m\u001b[0m\u001b[0m\n\u001b[1;32m   3468\u001b[0m \u001b[0;34m\u001b[0m\u001b[0m\n\u001b[0;32m-> 3469\u001b[0;31m         self.sagemaker_client.create_endpoint(\n\u001b[0m\u001b[1;32m   3470\u001b[0m             \u001b[0mEndpointName\u001b[0m\u001b[0;34m=\u001b[0m\u001b[0mendpoint_name\u001b[0m\u001b[0;34m,\u001b[0m \u001b[0mEndpointConfigName\u001b[0m\u001b[0;34m=\u001b[0m\u001b[0mconfig_name\u001b[0m\u001b[0;34m,\u001b[0m \u001b[0mTags\u001b[0m\u001b[0;34m=\u001b[0m\u001b[0mtags\u001b[0m\u001b[0;34m\u001b[0m\u001b[0;34m\u001b[0m\u001b[0m\n\u001b[1;32m   3471\u001b[0m         )\n",
      "\u001b[0;32m~/anaconda3/envs/pytorch_p39/lib/python3.9/site-packages/sagemaker/local/local_session.py\u001b[0m in \u001b[0;36mcreate_endpoint\u001b[0;34m(self, EndpointName, EndpointConfigName, Tags)\u001b[0m\n\u001b[1;32m    356\u001b[0m         \u001b[0mendpoint\u001b[0m \u001b[0;34m=\u001b[0m \u001b[0m_LocalEndpoint\u001b[0m\u001b[0;34m(\u001b[0m\u001b[0mEndpointName\u001b[0m\u001b[0;34m,\u001b[0m \u001b[0mEndpointConfigName\u001b[0m\u001b[0;34m,\u001b[0m \u001b[0mTags\u001b[0m\u001b[0;34m,\u001b[0m \u001b[0mself\u001b[0m\u001b[0;34m.\u001b[0m\u001b[0msagemaker_session\u001b[0m\u001b[0;34m)\u001b[0m\u001b[0;34m\u001b[0m\u001b[0;34m\u001b[0m\u001b[0m\n\u001b[1;32m    357\u001b[0m         \u001b[0mLocalSagemakerClient\u001b[0m\u001b[0;34m.\u001b[0m\u001b[0m_endpoints\u001b[0m\u001b[0;34m[\u001b[0m\u001b[0mEndpointName\u001b[0m\u001b[0;34m]\u001b[0m \u001b[0;34m=\u001b[0m \u001b[0mendpoint\u001b[0m\u001b[0;34m\u001b[0m\u001b[0;34m\u001b[0m\u001b[0m\n\u001b[0;32m--> 358\u001b[0;31m         \u001b[0mendpoint\u001b[0m\u001b[0;34m.\u001b[0m\u001b[0mserve\u001b[0m\u001b[0;34m(\u001b[0m\u001b[0;34m)\u001b[0m\u001b[0;34m\u001b[0m\u001b[0;34m\u001b[0m\u001b[0m\n\u001b[0m\u001b[1;32m    359\u001b[0m \u001b[0;34m\u001b[0m\u001b[0m\n\u001b[1;32m    360\u001b[0m     \u001b[0;32mdef\u001b[0m \u001b[0mupdate_endpoint\u001b[0m\u001b[0;34m(\u001b[0m\u001b[0mself\u001b[0m\u001b[0;34m,\u001b[0m \u001b[0mEndpointName\u001b[0m\u001b[0;34m,\u001b[0m \u001b[0mEndpointConfigName\u001b[0m\u001b[0;34m)\u001b[0m\u001b[0;34m:\u001b[0m  \u001b[0;31m# pylint: disable=unused-argument\u001b[0m\u001b[0;34m\u001b[0m\u001b[0;34m\u001b[0m\u001b[0m\n",
      "\u001b[0;32m~/anaconda3/envs/pytorch_p39/lib/python3.9/site-packages/sagemaker/local/entities.py\u001b[0m in \u001b[0;36mserve\u001b[0;34m(self)\u001b[0m\n\u001b[1;32m    606\u001b[0m \u001b[0;34m\u001b[0m\u001b[0m\n\u001b[1;32m    607\u001b[0m         \u001b[0mserving_port\u001b[0m \u001b[0;34m=\u001b[0m \u001b[0mget_config_value\u001b[0m\u001b[0;34m(\u001b[0m\u001b[0;34m\"local.serving_port\"\u001b[0m\u001b[0;34m,\u001b[0m \u001b[0mself\u001b[0m\u001b[0;34m.\u001b[0m\u001b[0mlocal_session\u001b[0m\u001b[0;34m.\u001b[0m\u001b[0mconfig\u001b[0m\u001b[0;34m)\u001b[0m \u001b[0;32mor\u001b[0m \u001b[0;36m8080\u001b[0m\u001b[0;34m\u001b[0m\u001b[0;34m\u001b[0m\u001b[0m\n\u001b[0;32m--> 608\u001b[0;31m         \u001b[0m_wait_for_serving_container\u001b[0m\u001b[0;34m(\u001b[0m\u001b[0mserving_port\u001b[0m\u001b[0;34m)\u001b[0m\u001b[0;34m\u001b[0m\u001b[0;34m\u001b[0m\u001b[0m\n\u001b[0m\u001b[1;32m    609\u001b[0m         \u001b[0;31m# the container is running and it passed the healthcheck status is now InService\u001b[0m\u001b[0;34m\u001b[0m\u001b[0;34m\u001b[0m\u001b[0m\n\u001b[1;32m    610\u001b[0m         \u001b[0mself\u001b[0m\u001b[0;34m.\u001b[0m\u001b[0mstate\u001b[0m \u001b[0;34m=\u001b[0m \u001b[0m_LocalEndpoint\u001b[0m\u001b[0;34m.\u001b[0m\u001b[0m_IN_SERVICE\u001b[0m\u001b[0;34m\u001b[0m\u001b[0;34m\u001b[0m\u001b[0m\n",
      "\u001b[0;32m~/anaconda3/envs/pytorch_p39/lib/python3.9/site-packages/sagemaker/local/entities.py\u001b[0m in \u001b[0;36m_wait_for_serving_container\u001b[0;34m(serving_port)\u001b[0m\n\u001b[1;32m    938\u001b[0m         \u001b[0mi\u001b[0m \u001b[0;34m+=\u001b[0m \u001b[0;36m5\u001b[0m\u001b[0;34m\u001b[0m\u001b[0;34m\u001b[0m\u001b[0m\n\u001b[1;32m    939\u001b[0m         \u001b[0;32mif\u001b[0m \u001b[0mi\u001b[0m \u001b[0;34m>=\u001b[0m \u001b[0mHEALTH_CHECK_TIMEOUT_LIMIT\u001b[0m\u001b[0;34m:\u001b[0m\u001b[0;34m\u001b[0m\u001b[0;34m\u001b[0m\u001b[0m\n\u001b[0;32m--> 940\u001b[0;31m             \u001b[0;32mraise\u001b[0m \u001b[0mRuntimeError\u001b[0m\u001b[0;34m(\u001b[0m\u001b[0;34m\"Giving up, endpoint didn't launch correctly\"\u001b[0m\u001b[0;34m)\u001b[0m\u001b[0;34m\u001b[0m\u001b[0;34m\u001b[0m\u001b[0m\n\u001b[0m\u001b[1;32m    941\u001b[0m \u001b[0;34m\u001b[0m\u001b[0m\n\u001b[1;32m    942\u001b[0m         \u001b[0mlogger\u001b[0m\u001b[0;34m.\u001b[0m\u001b[0minfo\u001b[0m\u001b[0;34m(\u001b[0m\u001b[0;34m\"Checking if serving container is up, attempt: %s\"\u001b[0m\u001b[0;34m,\u001b[0m \u001b[0mi\u001b[0m\u001b[0;34m)\u001b[0m\u001b[0;34m\u001b[0m\u001b[0;34m\u001b[0m\u001b[0m\n",
      "\u001b[0;31mRuntimeError\u001b[0m: Giving up, endpoint didn't launch correctly"
     ]
    }
   ],
   "source": [
    "experiment_name = pm.get_params(key=prefix + \"-EXPERI-NAME\")\n",
    "create_experiment(experiment_name)\n",
    "job_name = create_trial(experiment_name)\n",
    "\n",
    "\n",
    "predictor = model.deploy(\n",
    "    initial_instance_count=1,\n",
    "    instance_type=inference_instance_type,\n",
    "    data_capture_config=data_capture_config,\n",
    "    endpoint_name=job_name,\n",
    "    experiment_config={\n",
    "      'TrialName': job_name,\n",
    "      'TrialComponentDisplayName': job_name,\n",
    "    }\n",
    ")"
   ]
  },
  {
   "cell_type": "code",
   "execution_count": null,
   "id": "10b2bb45",
   "metadata": {
    "tags": []
   },
   "outputs": [],
   "source": [
    "paths2audio_files = f\"{os.getcwd()}/data/preprocessing/an4/wav/an4test_clstk/fcaw/an406-fcaw-b.wav\"\n",
    "paths2audio_files"
   ]
  },
  {
   "cell_type": "code",
   "execution_count": null,
   "id": "ecc9c485",
   "metadata": {
    "tags": []
   },
   "outputs": [],
   "source": [
    "import librosa\n",
    "import IPython.display as ipd\n",
    "\n",
    "# Load and listen to the audio file\n",
    "audio, sample_rate = librosa.load(paths2audio_files)\n",
    "\n",
    "ipd.Audio(paths2audio_files, rate=sample_rate)"
   ]
  },
  {
   "cell_type": "code",
   "execution_count": null,
   "id": "000a6dd0",
   "metadata": {},
   "outputs": [],
   "source": [
    "from sagemaker.serializers import DataSerializer\n",
    "predictor.serializer = DataSerializer()"
   ]
  },
  {
   "cell_type": "code",
   "execution_count": null,
   "id": "ef0b6896",
   "metadata": {},
   "outputs": [],
   "source": [
    "predictor.predict(paths2audio_files)"
   ]
  },
  {
   "cell_type": "code",
   "execution_count": null,
   "id": "fae1aa6b",
   "metadata": {
    "tags": []
   },
   "outputs": [],
   "source": [
    "pm.put_params(key=\"-\".join([prefix, \"ENDPOINT-NAME\"]), value=job_name, overwrite=True)\n",
    "pm.put_params(key=\"-\".join([prefix, \"MONITOR-OUTPUT\"]), value=monitor_output, overwrite=True)"
   ]
  },
  {
   "cell_type": "code",
   "execution_count": null,
   "id": "3aed4c8b",
   "metadata": {},
   "outputs": [],
   "source": [
    "# predictor.delete_endpoint()"
   ]
  }
 ],
 "metadata": {
  "instance_type": "ml.t3.medium",
  "kernelspec": {
   "display_name": "conda_pytorch_p39",
   "language": "python",
   "name": "conda_pytorch_p39"
  },
  "language_info": {
   "codemirror_mode": {
    "name": "ipython",
    "version": 3
   },
   "file_extension": ".py",
   "mimetype": "text/x-python",
   "name": "python",
   "nbconvert_exporter": "python",
   "pygments_lexer": "ipython3",
   "version": "3.9.15"
  }
 },
 "nbformat": 4,
 "nbformat_minor": 5
}
